>单个异常

```python
try:
    <语句>#运行别的代码
except <名字>:
    #如果在try部分引发了异常
    <语句>
```

```python
def fun(x,y):
    try:
        a=x/y
    except ZeroDivisionError:
        print("You can't divide by 0")
fun(2,0)
```

```
You can't divide by 0
```

>多个异常

```python
try:
    <语句>#运行别的代码
except <name1>:
    <语句>#引发name1异常
except <name2>:
    <语句>#引发name2异常
```

```python
def fun(x,y):
    try:
        b=name
        a=x/y
    except ZeroDivisionError:
        print("You can't divide by 0")
    except NameError:
        print("NameError")
fun(2,0)
```

```
NameError
```

```python
def fun(x,y):
    try:
        #b=name
        a=x/y
    except ZeroDivisionError:
        print("You can't divide by 0")
    except NameError:
        print("NameError")
fun(2,0)
```

```
You can't divide by 0
```

>异常中的else

```python
try:
    <语句>
except <名字>:
    <语句>
except <名字>:
    <语句>
else:
    <语句>#没有发生异常
```

```python
def fun(x,y):
    try:
        a=x/y
    except TypeError:
        print("TypeError")
    except ZeroDivisionError:
        print("You can't divide by 0")
    else:
        print(a)
fun(2,0)
fun(2,"0")
fun(2,1)
```

```
You can't divide by 0
TypeError
2.0
```

>finally子句

```python
def fun(x,y):
    try:
        a=x/y
    finally:
        print("asfd")
fun(2,0)
```

```
asfd
Traceback (most recent call last):
  File "/home/misaka/python/test3.py", line 6, in <module>
    fun(2,0)
  File "/home/misaka/python/test3.py", line 3, in fun
    a=x/y
ZeroDivisionError: division by zero
```

>无论try子句中是否发生异常,finally都会被执行